<?xml version="1.0" ?>
<sdf version="1.5">

<model name="cable">

  	<self_collide>true</self_collide>

  	<pose> 0 0 7.75 0 0 0</pose>

  	<!-- Enganche esférico inicial -->
  	<link name="link_0">
		<pose>0 0 0 0 0 0</pose>
		<collision name="sphere">
			<geometry>
				<sphere>
					<radius>0.015</radius>
				</sphere>
			</geometry>
		</collision>
		<visual name="sphere">
			<geometry>
				<sphere>
					<radius>0.015</radius>
				</sphere>
			</geometry>
			<material>
  <ambient>0 0 0 1</ambient>
  <emissive>0 0 0 1</emissive>
  <diffuse>0 0 0 1</diffuse>
  <specular>1 1 1 1</specular>
</material>

		</visual>
	</link>

	<joint name="world" type="fixed">
    	<child>link_0</child>
    	<parent>world</parent>
  	</joint>


	<link name="link_1">
	    <gravity>true</gravity>
	    <pose>0 0 -0.0 0 1.832595714594046 0</pose>
	    <inertial>
	      <pose>0 0 1 0 0 0</pose>
	      <mass>5</mass>
	      <inertia>
	        <ixx>1.6669479166666668</ixx>
	        <iyy>1.6669479166666668</iyy>
	        <izz>0.5</izz>
	      </inertia>
	    </inertial>

	    <collision name="cylinder">
	      	<pose>0 0 1 0 0 0</pose>
	      	<geometry>
		        <cylinder>
			        <length>2</length>
			        <radius>0.015</radius>
		        </cylinder>
	      	</geometry>
	      	<surface>
	        	<contact>
	          		<ode>
	            		<kp>1e5</kp>
	            		<kd>1</kd>
	            		<max_vel>0.1</max_vel>
	            		<min_depth>0.0015</min_depth>
	          		</ode>
	        	</contact>
	        	<friction>
	          		<ode>
			            <mu>1.0</mu>
	            		<mu2>1.0</mu2>
	          		</ode>
	        	</friction>
	      	</surface>
	    </collision>
	    <visual name="cylinder">
	      	<pose>0 0 1 0 0 0</pose>
	      	<geometry>
	        	<cylinder>
	          		<length>2</length>
	          		<radius>0.015</radius>
	        	</cylinder>
	      	</geometry>
	      	<material>
  <ambient>0 0 0 1</ambient>
  <emissive>0 0 0 1</emissive>
  <diffuse>0 0 0 1</diffuse>
  <specular>1 1 1 1</specular>
</material>

	    </visual>

	    <collision name="sphere">
			<geometry>
				<sphere>
					<radius>0.015</radius>
				</sphere>
			</geometry>
	    	<surface>
	        	<contact>
	        		<ode>
		            	<kp>1e5</kp>
		            	<kd>1</kd>
		            	<max_vel>0.1</max_vel>
		            	<min_depth>0.0015</min_depth>
	        		</ode>
	        	</contact>
	        	<friction>
	          		<ode>
	            		<mu>1.0</mu>
	            		<mu2>1.0</mu2>
	          		</ode>
	        	</friction>
	      	</surface>
	    </collision>
	    <visual name="sphere">
		    <geometry>
		        <sphere>
		          	<radius>0.015</radius>
		        </sphere>
		    </geometry>
		    <material>
  <ambient>0 0 0 1</ambient>
  <emissive>0 0 0 1</emissive>
  <diffuse>0 0 0 1</diffuse>
  <specular>1 1 1 1</specular>
</material>

	    </visual>
	</link>

	<joint name="joint_1" type="universal">
	    <child>link_1</child>
	    <parent>link_0</parent>
	    <axis>
	      	<xyz>0 1 0</xyz>
	      	<limit>
	        	<lower>-0.39269908169872414</lower>
	        	<upper>0.39269908169872414</upper>
	      	</limit>
	      	<dynamics>
	      		<friction>50</friction>
	      	</dynamics>
	    </axis>
	    <!--axis2>
	      	<xyz>-1 0 0</xyz>
	      	<limit>
	       		<lower>-0.7853981633974483</lower>
	        	<upper>0.7853981633974483</upper>
	      	</limit>
	      	<dynamics>
	      		<friction>50</friction>
	      	</dynamics>
	    </axis2-->
	    <physics>
	      	<ode>
		        <cfm_damping>0</cfm_damping>
	      	</ode>
	    </physics>
	</joint>

	<link name="link_2">
	    <gravity>true</gravity>
	    <pose>1.9318516525781366 0 -0.5176380902050415 0 1.832595714594046 0</pose>
	    <inertial>
	      <pose>0 0 1 0 0 0</pose>
	      <mass>5</mass>
	      <inertia>
	        <ixx>1.6669479166666668</ixx>
	        <iyy>1.6669479166666668</iyy>
	        <izz>0.5</izz>
	      </inertia>
	    </inertial>

	    <collision name="cylinder">
	      	<pose>0 0 1 0 0 0</pose>
	      	<geometry>
		        <cylinder>
			        <length>2</length>
			        <radius>0.015</radius>
		        </cylinder>
	      	</geometry>
	      	<surface>
	        	<contact>
	          		<ode>
	            		<kp>1e5</kp>
	            		<kd>1</kd>
	            		<max_vel>0.1</max_vel>
	            		<min_depth>0.0015</min_depth>
	          		</ode>
	        	</contact>
	        	<friction>
	          		<ode>
			            <mu>1.0</mu>
	            		<mu2>1.0</mu2>
	          		</ode>
	        	</friction>
	      	</surface>
	    </collision>
	    <visual name="cylinder">
	      	<pose>0 0 1 0 0 0</pose>
	      	<geometry>
	        	<cylinder>
	          		<length>2</length>
	          		<radius>0.015</radius>
	        	</cylinder>
	      	</geometry>
	      	<material>
  <ambient>0 0 0 1</ambient>
  <emissive>0 0 0 1</emissive>
  <diffuse>0 0 0 1</diffuse>
  <specular>1 1 1 1</specular>
</material>

	    </visual>

	    <collision name="sphere">
			<geometry>
				<sphere>
					<radius>0.015</radius>
				</sphere>
			</geometry>
	    	<surface>
	        	<contact>
	        		<ode>
		            	<kp>1e5</kp>
		            	<kd>1</kd>
		            	<max_vel>0.1</max_vel>
		            	<min_depth>0.0015</min_depth>
	        		</ode>
	        	</contact>
	        	<friction>
	          		<ode>
	            		<mu>1.0</mu>
	            		<mu2>1.0</mu2>
	          		</ode>
	        	</friction>
	      	</surface>
	    </collision>
	    <visual name="sphere">
		    <geometry>
		        <sphere>
		          	<radius>0.015</radius>
		        </sphere>
		    </geometry>
		    <material>
  <ambient>0 0 0 1</ambient>
  <emissive>0 0 0 1</emissive>
  <diffuse>0 0 0 1</diffuse>
  <specular>1 1 1 1</specular>
</material>

	    </visual>
	</link>

	<joint name="joint_2" type="universal">
	    <child>link_2</child>
	    <parent>link_1</parent>
	    <axis>
	      	<xyz>0 1 0</xyz>
	      	<limit>
	        	<lower>-0.39269908169872414</lower>
	        	<upper>0.39269908169872414</upper>
	      	</limit>
	      	<dynamics>
	      		<friction>50</friction>
	      	</dynamics>
	    </axis>
	    <!--axis2>
	      	<xyz>-1 0 0</xyz>
	      	<limit>
	       		<lower>-0.7853981633974483</lower>
	        	<upper>0.7853981633974483</upper>
	      	</limit>
	      	<dynamics>
	      		<friction>50</friction>
	      	</dynamics>
	    </axis2-->
	    <physics>
	      	<ode>
		        <cfm_damping>0</cfm_damping>
	      	</ode>
	    </physics>
	</joint>

	<link name="link_3">
	    <gravity>true</gravity>
	    <pose>3.8637033051562732 0 -1.035276180410083 0 1.832595714594046 0</pose>
	    <inertial>
	      <pose>0 0 1 0 0 0</pose>
	      <mass>5</mass>
	      <inertia>
	        <ixx>1.6669479166666668</ixx>
	        <iyy>1.6669479166666668</iyy>
	        <izz>0.5</izz>
	      </inertia>
	    </inertial>

	    <collision name="cylinder">
	      	<pose>0 0 1 0 0 0</pose>
	      	<geometry>
		        <cylinder>
			        <length>2</length>
			        <radius>0.015</radius>
		        </cylinder>
	      	</geometry>
	      	<surface>
	        	<contact>
	          		<ode>
	            		<kp>1e5</kp>
	            		<kd>1</kd>
	            		<max_vel>0.1</max_vel>
	            		<min_depth>0.0015</min_depth>
	          		</ode>
	        	</contact>
	        	<friction>
	          		<ode>
			            <mu>1.0</mu>
	            		<mu2>1.0</mu2>
	          		</ode>
	        	</friction>
	      	</surface>
	    </collision>
	    <visual name="cylinder">
	      	<pose>0 0 1 0 0 0</pose>
	      	<geometry>
	        	<cylinder>
	          		<length>2</length>
	          		<radius>0.015</radius>
	        	</cylinder>
	      	</geometry>
	      	<material>
  <ambient>0 0 0 1</ambient>
  <emissive>0 0 0 1</emissive>
  <diffuse>0 0 0 1</diffuse>
  <specular>1 1 1 1</specular>
</material>

	    </visual>

	    <collision name="sphere">
			<geometry>
				<sphere>
					<radius>0.015</radius>
				</sphere>
			</geometry>
	    	<surface>
	        	<contact>
	        		<ode>
		            	<kp>1e5</kp>
		            	<kd>1</kd>
		            	<max_vel>0.1</max_vel>
		            	<min_depth>0.0015</min_depth>
	        		</ode>
	        	</contact>
	        	<friction>
	          		<ode>
	            		<mu>1.0</mu>
	            		<mu2>1.0</mu2>
	          		</ode>
	        	</friction>
	      	</surface>
	    </collision>
	    <visual name="sphere">
		    <geometry>
		        <sphere>
		          	<radius>0.015</radius>
		        </sphere>
		    </geometry>
		    <material>
  <ambient>0 0 0 1</ambient>
  <emissive>0 0 0 1</emissive>
  <diffuse>0 0 0 1</diffuse>
  <specular>1 1 1 1</specular>
</material>

	    </visual>
	</link>

	<joint name="joint_3" type="universal">
	    <child>link_3</child>
	    <parent>link_2</parent>
	    <axis>
	      	<xyz>0 1 0</xyz>
	      	<limit>
	        	<lower>-0.39269908169872414</lower>
	        	<upper>0.39269908169872414</upper>
	      	</limit>
	      	<dynamics>
	      		<friction>50</friction>
	      	</dynamics>
	    </axis>
	    <!--axis2>
	      	<xyz>-1 0 0</xyz>
	      	<limit>
	       		<lower>-0.7853981633974483</lower>
	        	<upper>0.7853981633974483</upper>
	      	</limit>
	      	<dynamics>
	      		<friction>50</friction>
	      	</dynamics>
	    </axis2-->
	    <physics>
	      	<ode>
		        <cfm_damping>0</cfm_damping>
	      	</ode>
	    </physics>
	</joint>

	<link name="link_4">
	    <gravity>true</gravity>
	    <pose>5.79555495773441 0 -1.5529142706151244 0 1.832595714594046 0</pose>
	    <inertial>
	      <pose>0 0 1 0 0 0</pose>
	      <mass>5</mass>
	      <inertia>
	        <ixx>1.6669479166666668</ixx>
	        <iyy>1.6669479166666668</iyy>
	        <izz>0.5</izz>
	      </inertia>
	    </inertial>

	    <collision name="cylinder">
	      	<pose>0 0 1 0 0 0</pose>
	      	<geometry>
		        <cylinder>
			        <length>2</length>
			        <radius>0.015</radius>
		        </cylinder>
	      	</geometry>
	      	<surface>
	        	<contact>
	          		<ode>
	            		<kp>1e5</kp>
	            		<kd>1</kd>
	            		<max_vel>0.1</max_vel>
	            		<min_depth>0.0015</min_depth>
	          		</ode>
	        	</contact>
	        	<friction>
	          		<ode>
			            <mu>1.0</mu>
	            		<mu2>1.0</mu2>
	          		</ode>
	        	</friction>
	      	</surface>
	    </collision>
	    <visual name="cylinder">
	      	<pose>0 0 1 0 0 0</pose>
	      	<geometry>
	        	<cylinder>
	          		<length>2</length>
	          		<radius>0.015</radius>
	        	</cylinder>
	      	</geometry>
	      	<material>
  <ambient>0 0 0 1</ambient>
  <emissive>0 0 0 1</emissive>
  <diffuse>0 0 0 1</diffuse>
  <specular>1 1 1 1</specular>
</material>

	    </visual>

	    <collision name="sphere">
			<geometry>
				<sphere>
					<radius>0.015</radius>
				</sphere>
			</geometry>
	    	<surface>
	        	<contact>
	        		<ode>
		            	<kp>1e5</kp>
		            	<kd>1</kd>
		            	<max_vel>0.1</max_vel>
		            	<min_depth>0.0015</min_depth>
	        		</ode>
	        	</contact>
	        	<friction>
	          		<ode>
	            		<mu>1.0</mu>
	            		<mu2>1.0</mu2>
	          		</ode>
	        	</friction>
	      	</surface>
	    </collision>
	    <visual name="sphere">
		    <geometry>
		        <sphere>
		          	<radius>0.015</radius>
		        </sphere>
		    </geometry>
		    <material>
  <ambient>0 0 0 1</ambient>
  <emissive>0 0 0 1</emissive>
  <diffuse>0 0 0 1</diffuse>
  <specular>1 1 1 1</specular>
</material>

	    </visual>
	</link>

	<joint name="joint_4" type="universal">
	    <child>link_4</child>
	    <parent>link_3</parent>
	    <axis>
	      	<xyz>0 1 0</xyz>
	      	<limit>
	        	<lower>-0.39269908169872414</lower>
	        	<upper>0.39269908169872414</upper>
	      	</limit>
	      	<dynamics>
	      		<friction>50</friction>
	      	</dynamics>
	    </axis>
	    <!--axis2>
	      	<xyz>-1 0 0</xyz>
	      	<limit>
	       		<lower>-0.7853981633974483</lower>
	        	<upper>0.7853981633974483</upper>
	      	</limit>
	      	<dynamics>
	      		<friction>50</friction>
	      	</dynamics>
	    </axis2-->
	    <physics>
	      	<ode>
		        <cfm_damping>0</cfm_damping>
	      	</ode>
	    </physics>
	</joint>

	<link name="link_5">
	    <gravity>true</gravity>
	    <pose>7.7274066103125465 0 -2.070552360820166 0 1.5707963267948966 0</pose>
	    <inertial>
	      <pose>0 0 1 0 0 0</pose>
	      <mass>5</mass>
	      <inertia>
	        <ixx>1.6669479166666668</ixx>
	        <iyy>1.6669479166666668</iyy>
	        <izz>0.5</izz>
	      </inertia>
	    </inertial>

	    <collision name="cylinder">
	      	<pose>0 0 1 0 0 0</pose>
	      	<geometry>
		        <cylinder>
			        <length>2</length>
			        <radius>0.015</radius>
		        </cylinder>
	      	</geometry>
	      	<surface>
	        	<contact>
	          		<ode>
	            		<kp>1e5</kp>
	            		<kd>1</kd>
	            		<max_vel>0.1</max_vel>
	            		<min_depth>0.0015</min_depth>
	          		</ode>
	        	</contact>
	        	<friction>
	          		<ode>
			            <mu>1.0</mu>
	            		<mu2>1.0</mu2>
	          		</ode>
	        	</friction>
	      	</surface>
	    </collision>
	    <visual name="cylinder">
	      	<pose>0 0 1 0 0 0</pose>
	      	<geometry>
	        	<cylinder>
	          		<length>2</length>
	          		<radius>0.015</radius>
	        	</cylinder>
	      	</geometry>
	      	<material>
  <ambient>0 0 0 1</ambient>
  <emissive>0 0 0 1</emissive>
  <diffuse>0 0 0 1</diffuse>
  <specular>1 1 1 1</specular>
</material>

	    </visual>

	    <collision name="sphere">
			<geometry>
				<sphere>
					<radius>0.015</radius>
				</sphere>
			</geometry>
	    	<surface>
	        	<contact>
	        		<ode>
		            	<kp>1e5</kp>
		            	<kd>1</kd>
		            	<max_vel>0.1</max_vel>
		            	<min_depth>0.0015</min_depth>
	        		</ode>
	        	</contact>
	        	<friction>
	          		<ode>
	            		<mu>1.0</mu>
	            		<mu2>1.0</mu2>
	          		</ode>
	        	</friction>
	      	</surface>
	    </collision>
	    <visual name="sphere">
		    <geometry>
		        <sphere>
		          	<radius>0.015</radius>
		        </sphere>
		    </geometry>
		    <material>
  <ambient>0 0 0 1</ambient>
  <emissive>0 0 0 1</emissive>
  <diffuse>0 0 0 1</diffuse>
  <specular>1 1 1 1</specular>
</material>

	    </visual>
	</link>

	<joint name="joint_5" type="universal">
	    <child>link_5</child>
	    <parent>link_4</parent>
	    <axis>
	      	<xyz>0 1 0</xyz>
	      	<limit>
	        	<lower>-0.39269908169872414</lower>
	        	<upper>0.39269908169872414</upper>
	      	</limit>
	      	<dynamics>
	      		<friction>50</friction>
	      	</dynamics>
	    </axis>
	    <!--axis2>
	      	<xyz>-1 0 0</xyz>
	      	<limit>
	       		<lower>-0.7853981633974483</lower>
	        	<upper>0.7853981633974483</upper>
	      	</limit>
	      	<dynamics>
	      		<friction>50</friction>
	      	</dynamics>
	    </axis2-->
	    <physics>
	      	<ode>
		        <cfm_damping>0</cfm_damping>
	      	</ode>
	    </physics>
	</joint>

	<link name="link_6">
	    <gravity>true</gravity>
	    <pose>9.727406610312546 0 -2.070552360820166 0 1.3089969389957472 0</pose>
	    <inertial>
	      <pose>0 0 1 0 0 0</pose>
	      <mass>5</mass>
	      <inertia>
	        <ixx>1.6669479166666668</ixx>
	        <iyy>1.6669479166666668</iyy>
	        <izz>0.5</izz>
	      </inertia>
	    </inertial>

	    <collision name="cylinder">
	      	<pose>0 0 1 0 0 0</pose>
	      	<geometry>
		        <cylinder>
			        <length>2</length>
			        <radius>0.015</radius>
		        </cylinder>
	      	</geometry>
	      	<surface>
	        	<contact>
	          		<ode>
	            		<kp>1e5</kp>
	            		<kd>1</kd>
	            		<max_vel>0.1</max_vel>
	            		<min_depth>0.0015</min_depth>
	          		</ode>
	        	</contact>
	        	<friction>
	          		<ode>
			            <mu>1.0</mu>
	            		<mu2>1.0</mu2>
	          		</ode>
	        	</friction>
	      	</surface>
	    </collision>
	    <visual name="cylinder">
	      	<pose>0 0 1 0 0 0</pose>
	      	<geometry>
	        	<cylinder>
	          		<length>2</length>
	          		<radius>0.015</radius>
	        	</cylinder>
	      	</geometry>
	      	<material>
  <ambient>0 0 0 1</ambient>
  <emissive>0 0 0 1</emissive>
  <diffuse>0 0 0 1</diffuse>
  <specular>1 1 1 1</specular>
</material>

	    </visual>

	    <collision name="sphere">
			<geometry>
				<sphere>
					<radius>0.015</radius>
				</sphere>
			</geometry>
	    	<surface>
	        	<contact>
	        		<ode>
		            	<kp>1e5</kp>
		            	<kd>1</kd>
		            	<max_vel>0.1</max_vel>
		            	<min_depth>0.0015</min_depth>
	        		</ode>
	        	</contact>
	        	<friction>
	          		<ode>
	            		<mu>1.0</mu>
	            		<mu2>1.0</mu2>
	          		</ode>
	        	</friction>
	      	</surface>
	    </collision>
	    <visual name="sphere">
		    <geometry>
		        <sphere>
		          	<radius>0.015</radius>
		        </sphere>
		    </geometry>
		    <material>
  <ambient>0 0 0 1</ambient>
  <emissive>0 0 0 1</emissive>
  <diffuse>0 0 0 1</diffuse>
  <specular>1 1 1 1</specular>
</material>

	    </visual>
	</link>

	<joint name="joint_6" type="universal">
	    <child>link_6</child>
	    <parent>link_5</parent>
	    <axis>
	      	<xyz>0 1 0</xyz>
	      	<limit>
	        	<lower>-0.39269908169872414</lower>
	        	<upper>0.39269908169872414</upper>
	      	</limit>
	      	<dynamics>
	      		<friction>50</friction>
	      	</dynamics>
	    </axis>
	    <!--axis2>
	      	<xyz>-1 0 0</xyz>
	      	<limit>
	       		<lower>-0.7853981633974483</lower>
	        	<upper>0.7853981633974483</upper>
	      	</limit>
	      	<dynamics>
	      		<friction>50</friction>
	      	</dynamics>
	    </axis2-->
	    <physics>
	      	<ode>
		        <cfm_damping>0</cfm_damping>
	      	</ode>
	    </physics>
	</joint>

	<link name="link_7">
	    <gravity>true</gravity>
	    <pose>11.659258262890683 0 -1.5529142706151244 0 1.3089969389957472 0</pose>
	    <inertial>
	      <pose>0 0 1 0 0 0</pose>
	      <mass>5</mass>
	      <inertia>
	        <ixx>1.6669479166666668</ixx>
	        <iyy>1.6669479166666668</iyy>
	        <izz>0.5</izz>
	      </inertia>
	    </inertial>

	    <collision name="cylinder">
	      	<pose>0 0 1 0 0 0</pose>
	      	<geometry>
		        <cylinder>
			        <length>2</length>
			        <radius>0.015</radius>
		        </cylinder>
	      	</geometry>
	      	<surface>
	        	<contact>
	          		<ode>
	            		<kp>1e5</kp>
	            		<kd>1</kd>
	            		<max_vel>0.1</max_vel>
	            		<min_depth>0.0015</min_depth>
	          		</ode>
	        	</contact>
	        	<friction>
	          		<ode>
			            <mu>1.0</mu>
	            		<mu2>1.0</mu2>
	          		</ode>
	        	</friction>
	      	</surface>
	    </collision>
	    <visual name="cylinder">
	      	<pose>0 0 1 0 0 0</pose>
	      	<geometry>
	        	<cylinder>
	          		<length>2</length>
	          		<radius>0.015</radius>
	        	</cylinder>
	      	</geometry>
	      	<material>
  <ambient>0 0 0 1</ambient>
  <emissive>0 0 0 1</emissive>
  <diffuse>0 0 0 1</diffuse>
  <specular>1 1 1 1</specular>
</material>

	    </visual>

	    <collision name="sphere">
			<geometry>
				<sphere>
					<radius>0.015</radius>
				</sphere>
			</geometry>
	    	<surface>
	        	<contact>
	        		<ode>
		            	<kp>1e5</kp>
		            	<kd>1</kd>
		            	<max_vel>0.1</max_vel>
		            	<min_depth>0.0015</min_depth>
	        		</ode>
	        	</contact>
	        	<friction>
	          		<ode>
	            		<mu>1.0</mu>
	            		<mu2>1.0</mu2>
	          		</ode>
	        	</friction>
	      	</surface>
	    </collision>
	    <visual name="sphere">
		    <geometry>
		        <sphere>
		          	<radius>0.015</radius>
		        </sphere>
		    </geometry>
		    <material>
  <ambient>0 0 0 1</ambient>
  <emissive>0 0 0 1</emissive>
  <diffuse>0 0 0 1</diffuse>
  <specular>1 1 1 1</specular>
</material>

	    </visual>
	</link>

	<joint name="joint_7" type="universal">
	    <child>link_7</child>
	    <parent>link_6</parent>
	    <axis>
	      	<xyz>0 1 0</xyz>
	      	<limit>
	        	<lower>-0.39269908169872414</lower>
	        	<upper>0.39269908169872414</upper>
	      	</limit>
	      	<dynamics>
	      		<friction>50</friction>
	      	</dynamics>
	    </axis>
	    <!--axis2>
	      	<xyz>-1 0 0</xyz>
	      	<limit>
	       		<lower>-0.7853981633974483</lower>
	        	<upper>0.7853981633974483</upper>
	      	</limit>
	      	<dynamics>
	      		<friction>50</friction>
	      	</dynamics>
	    </axis2-->
	    <physics>
	      	<ode>
		        <cfm_damping>0</cfm_damping>
	      	</ode>
	    </physics>
	</joint>

	<link name="link_8">
	    <gravity>true</gravity>
	    <pose>13.59110991546882 0 -1.035276180410083 0 1.3089969389957472 0</pose>
	    <inertial>
	      <pose>0 0 1 0 0 0</pose>
	      <mass>5</mass>
	      <inertia>
	        <ixx>1.6669479166666668</ixx>
	        <iyy>1.6669479166666668</iyy>
	        <izz>0.5</izz>
	      </inertia>
	    </inertial>

	    <collision name="cylinder">
	      	<pose>0 0 1 0 0 0</pose>
	      	<geometry>
		        <cylinder>
			        <length>2</length>
			        <radius>0.015</radius>
		        </cylinder>
	      	</geometry>
	      	<surface>
	        	<contact>
	          		<ode>
	            		<kp>1e5</kp>
	            		<kd>1</kd>
	            		<max_vel>0.1</max_vel>
	            		<min_depth>0.0015</min_depth>
	          		</ode>
	        	</contact>
	        	<friction>
	          		<ode>
			            <mu>1.0</mu>
	            		<mu2>1.0</mu2>
	          		</ode>
	        	</friction>
	      	</surface>
	    </collision>
	    <visual name="cylinder">
	      	<pose>0 0 1 0 0 0</pose>
	      	<geometry>
	        	<cylinder>
	          		<length>2</length>
	          		<radius>0.015</radius>
	        	</cylinder>
	      	</geometry>
	      	<material>
  <ambient>0 0 0 1</ambient>
  <emissive>0 0 0 1</emissive>
  <diffuse>0 0 0 1</diffuse>
  <specular>1 1 1 1</specular>
</material>

	    </visual>

	    <collision name="sphere">
			<geometry>
				<sphere>
					<radius>0.015</radius>
				</sphere>
			</geometry>
	    	<surface>
	        	<contact>
	        		<ode>
		            	<kp>1e5</kp>
		            	<kd>1</kd>
		            	<max_vel>0.1</max_vel>
		            	<min_depth>0.0015</min_depth>
	        		</ode>
	        	</contact>
	        	<friction>
	          		<ode>
	            		<mu>1.0</mu>
	            		<mu2>1.0</mu2>
	          		</ode>
	        	</friction>
	      	</surface>
	    </collision>
	    <visual name="sphere">
		    <geometry>
		        <sphere>
		          	<radius>0.015</radius>
		        </sphere>
		    </geometry>
		    <material>
  <ambient>0 0 0 1</ambient>
  <emissive>0 0 0 1</emissive>
  <diffuse>0 0 0 1</diffuse>
  <specular>1 1 1 1</specular>
</material>

	    </visual>
	</link>

	<joint name="joint_8" type="universal">
	    <child>link_8</child>
	    <parent>link_7</parent>
	    <axis>
	      	<xyz>0 1 0</xyz>
	      	<limit>
	        	<lower>-0.39269908169872414</lower>
	        	<upper>0.39269908169872414</upper>
	      	</limit>
	      	<dynamics>
	      		<friction>50</friction>
	      	</dynamics>
	    </axis>
	    <!--axis2>
	      	<xyz>-1 0 0</xyz>
	      	<limit>
	       		<lower>-0.7853981633974483</lower>
	        	<upper>0.7853981633974483</upper>
	      	</limit>
	      	<dynamics>
	      		<friction>50</friction>
	      	</dynamics>
	    </axis2-->
	    <physics>
	      	<ode>
		        <cfm_damping>0</cfm_damping>
	      	</ode>
	    </physics>
	</joint>

	<link name="link_9">
	    <gravity>true</gravity>
	    <pose>15.522961568046957 0 -0.5176380902050415 0 1.3089969389957472 0</pose>
	    <inertial>
	      <pose>0 0 1 0 0 0</pose>
	      <mass>5</mass>
	      <inertia>
	        <ixx>1.6669479166666668</ixx>
	        <iyy>1.6669479166666668</iyy>
	        <izz>0.5</izz>
	      </inertia>
	    </inertial>

	    <collision name="cylinder">
	      	<pose>0 0 1 0 0 0</pose>
	      	<geometry>
		        <cylinder>
			        <length>2</length>
			        <radius>0.015</radius>
		        </cylinder>
	      	</geometry>
	      	<surface>
	        	<contact>
	          		<ode>
	            		<kp>1e5</kp>
	            		<kd>1</kd>
	            		<max_vel>0.1</max_vel>
	            		<min_depth>0.0015</min_depth>
	          		</ode>
	        	</contact>
	        	<friction>
	          		<ode>
			            <mu>1.0</mu>
	            		<mu2>1.0</mu2>
	          		</ode>
	        	</friction>
	      	</surface>
	    </collision>
	    <visual name="cylinder">
	      	<pose>0 0 1 0 0 0</pose>
	      	<geometry>
	        	<cylinder>
	          		<length>2</length>
	          		<radius>0.015</radius>
	        	</cylinder>
	      	</geometry>
	      	<material>
  <ambient>0 0 0 1</ambient>
  <emissive>0 0 0 1</emissive>
  <diffuse>0 0 0 1</diffuse>
  <specular>1 1 1 1</specular>
</material>

	    </visual>

	    <collision name="sphere">
			<geometry>
				<sphere>
					<radius>0.015</radius>
				</sphere>
			</geometry>
	    	<surface>
	        	<contact>
	        		<ode>
		            	<kp>1e5</kp>
		            	<kd>1</kd>
		            	<max_vel>0.1</max_vel>
		            	<min_depth>0.0015</min_depth>
	        		</ode>
	        	</contact>
	        	<friction>
	          		<ode>
	            		<mu>1.0</mu>
	            		<mu2>1.0</mu2>
	          		</ode>
	        	</friction>
	      	</surface>
	    </collision>
	    <visual name="sphere">
		    <geometry>
		        <sphere>
		          	<radius>0.015</radius>
		        </sphere>
		    </geometry>
		    <material>
  <ambient>0 0 0 1</ambient>
  <emissive>0 0 0 1</emissive>
  <diffuse>0 0 0 1</diffuse>
  <specular>1 1 1 1</specular>
</material>

	    </visual>
	</link>

	<joint name="joint_9" type="universal">
	    <child>link_9</child>
	    <parent>link_8</parent>
	    <axis>
	      	<xyz>0 1 0</xyz>
	      	<limit>
	        	<lower>-0.39269908169872414</lower>
	        	<upper>0.39269908169872414</upper>
	      	</limit>
	      	<dynamics>
	      		<friction>50</friction>
	      	</dynamics>
	    </axis>
	    <!--axis2>
	      	<xyz>-1 0 0</xyz>
	      	<limit>
	       		<lower>-0.7853981633974483</lower>
	        	<upper>0.7853981633974483</upper>
	      	</limit>
	      	<dynamics>
	      		<friction>50</friction>
	      	</dynamics>
	    </axis2-->
	    <physics>
	      	<ode>
		        <cfm_damping>0</cfm_damping>
	      	</ode>
	    </physics>
	</joint>

	<!-- Enganche esférico final -->
  	<link name="link_end">
		<pose>17.454813220625095 0 0 0 0 0</pose>
		<collision name="sphere">
			<geometry>
				<sphere>
					<radius>0.015</radius>
				</sphere>
			</geometry>
		</collision>
		<visual name="sphere">
			<geometry>
				<sphere>
					<radius>0.015</radius>
				</sphere>
			</geometry>
			<material>
  <ambient>0 0 0 1</ambient>
  <emissive>0 0 0 1</emissive>
  <diffuse>0 0 0 1</diffuse>
  <specular>1 1 1 1</specular>
</material>

		</visual>
	</link>

	<joint name="joint_10" type="universal">
	    <child>link_9</child>
	    <parent>link_end</parent>
	    <pose>0 0 2 0 0 0</pose>
	    <axis>
	      	<xyz>0 1 0</xyz>
	      	<limit>
	        	<lower>-0.39269908169872414</lower>
	        	<upper>0.39269908169872414</upper>
	      	</limit>
	    </axis>
	    <!--axis2>
	      	<xyz>-1 0 0</xyz>
	      	<limit>
	       		<lower>-0.7853981633974483</lower>
	        	<upper>0.7853981633974483</upper>
	      	</limit>
	    </axis2-->
	    <physics>
	      	<ode>
		        <cfm_damping>0</cfm_damping>
	      	</ode>
	    </physics>
	</joint>

  	<joint name="world_2" type="fixed">
	    <child>link_end</child>
    	<parent>world</parent>
	</joint>

</model>
</sdf>

<!-- Longitud final del cable: 17.454813220625095 -->